# ch6-9 예외

어떤 것을 처리하고 있는데 오류가 났을 때 어떻게 처리할까라고 하는 측면에서 2가지 방법이 있다.

명확하게 어떤 오류인지 반환 값을 주는 경우가 있고 오류가 날지, 나지 않을지 불명확한 상황이 있을 수 있다.

이런 불명확한 상황에서 예외라고 하는 구문을 사용할 수 있다.

<br>

## try catch문

```js
function doException() {
  // 예외를 발생시키는 구문
  throw new Error('오류');
}
function main() {
  doException();
}

main();
```

`throw`는 던진다는 뜻으로 예외를 던진다는 의미이다. 이 던진걸 어디에서도 받아주지 않으면 최종적으로 종료가 된다.

그래서 예외를 받아서 처리하기 위해서 `try catch`문을 사용한다.

```js
function main() {
  try {
    doException();
  } catch (e) {
    console.log(e);
  } finally {
    console.log('done');
  }
}
```

try는 무언가를 시도하는 것으로 예외가 있을지 없을지 모르지만 일단 시도해보는 동작을 한다.

만약 예외가 발생하면 catch로 받아주고 예외로 넘어온 데이터를 인자로 받을 수 있다.

예외가 있든 없든 최종적으로 실행해야 될 코드가 있다면 finally에 작성하면 된다.

<br>

### 예외의 특징

예외가 발생했을 때 함수 호출의 뎁스에 상관없이 함수의 바깥으로 계속 예외를 던진다.

그래서 바깥 함수 중에 어떤 함수든 catch로 잡기만 하면 된다.

이러한 특징으로 인해 다음과 같은 유연성을 발휘할 수 있다.

```js
function callException(type) {
  if (type === 'do') {
    doException();
  } else {
    noException();
  }
}

function main() {
  try {
    callException('do');
  } catch (e) {
    console.log(e);
  } finally {
    console.log('done');
  }
}
```

callException 함수는 전달받은 인자에 따라 예외를 발생시키는 함수가 실행된다.

예외는 callException 내부에서 발생했지만 main에서 catch로 잡아줄 수 있다.

그래서 오류 처리를 맨 상단에서 일원화해서 처리하고 싶을 때 throw구문을 이용해서 효과적으로 처리할 수 있게 된다.
